#VRML_SIM R2019a utf8
WorldInfo {
}
Viewpoint {
  orientation -0.16695186861184974 0.9709059480443739 0.17166453803586587 1.6281272242555898
  position 4.25336284492298 2.2829048871529136 0.10933728576234986
}
TexturedBackground {
}
TexturedBackgroundLight {
}
Floor {
}
DEF S_BOX_BOTTOM Solid {
  translation 0 0.025 0
  children [
    Shape {
      appearance DEF A_RED_BOTTOM PBRAppearance {
        baseColor 0.8 0 0
      }
      geometry Box {
        size 1 0.05 1
      }
    }
  ]
}
DEF S_BOX_FACE Solid {
  translation 0 0.01 0
  children [
    DEF G_RED_FACE Group {
    }
    Transform {
      translation -0.45 0.49 0.495
      children [
        Shape {
          appearance DEF A_RED_FACE PBRAppearance {
            baseColor 0.4470588235294118 0.6235294117647059 0.8117647058823529
          }
          geometry DEF G_RED_FACE Box {
            size 0.1 0.9 0.01
          }
        }
        Transform {
          children [
            Solid {
              translation 0.9 0 0
              children [
                Shape {
                  appearance USE A_RED_FACE
                  geometry Box {
                    size 0.1 0.9 0.01
                  }
                }
                Solid {
                  translation -0.45 -0.4 0
                  rotation 0 0 1 1.5707996938995747
                  children [
                    Shape {
                      appearance USE A_RED_FACE
                      geometry Box {
                        size 0.1 0.9 0.01
                      }
                    }
                    Solid {
                      translation 0.8 0 0
                      children [
                        Shape {
                          appearance USE A_RED_FACE
                          geometry Box {
                            size 0.1 0.9 0.01
                          }
                        }
                      ]
                    }
                    Solid {
                      translation 0.4 0 0
                      rotation 0 0 1 0.72
                      children [
                        Shape {
                          appearance USE A_RED_FACE
                          geometry Box {
                            size 0.07 1.1 0.01
                          }
                        }
                        Solid {
                          rotation 0 0 1 -1.4398996938995747
                          children [
                            Shape {
                              appearance USE A_RED_FACE
                              geometry Box {
                                size 0.07 1.1 0.01
                              }
                            }
                          ]
                        }
                      ]
                      name "solid(1)"
                    }
                  ]
                }
              ]
            }
          ]
        }
      ]
    }
  ]
  name "solid(1)"
}
DEF S_BOX_FACE2 Solid {
  translation -0.45 0.5 -0.495
  children [
    Group {
      children [
        Transform {
        }
        Shape {
          appearance USE A_RED_FACE
          geometry Box {
            size 0.1 0.9 0.01
          }
        }
        Transform {
          translation 0.9 0 0
          children [
            Shape {
              appearance USE A_RED_FACE
              geometry Box {
                size 0.1 0.9 0.01
              }
            }
          ]
        }
        Transform {
          translation 0.45 -0.4 0
          rotation 0 0 1 1.5707996938995747
          children [
            Shape {
              appearance USE A_RED_FACE
              geometry Box {
                size 0.1 0.9 0.01
              }
            }
          ]
        }
        Transform {
          translation 0.45 0.4 0
          rotation 0 0 1 1.5707996938995747
          children [
            Shape {
              appearance USE A_RED_FACE
              geometry Box {
                size 0.1 0.9 0.01
              }
            }
          ]
        }
        Transform {
          translation 0.45 0 0
          rotation 0 0 1 0.8554
          children [
            Shape {
              appearance USE A_RED_FACE
              geometry Box {
                size 0.07 1.1 0.01
              }
            }
          ]
        }
        Transform {
          translation 0.45 0 0
          rotation 0 0 1 -0.859
          children [
            Shape {
              appearance USE A_RED_FACE
              geometry Box {
                size 0.07 1.1 0.01
              }
            }
          ]
        }
      ]
    }
  ]
  name "solid(2)"
}
DEF S_BOX_FACE3 Solid {
  translation -0.495 0.5 0.45
  rotation 0 1 0 1.5708003061004252
  children [
    Group {
      children [
        Transform {
        }
        Shape {
          appearance DEF A_ORANGE_FACE PBRAppearance {
            baseColor 0.9607843137254902 0.4745098039215686 0
          }
          geometry Box {
            size 0.08 0.9 0.01
          }
        }
        Transform {
          translation 0.9 0 0
          children [
            Shape {
              appearance USE A_ORANGE_FACE
              geometry Box {
                size 0.08 0.9 0.01
              }
            }
          ]
        }
        Transform {
          translation 0.45 -0.4 0
          rotation 0 0 1 1.5707996938995747
          children [
            Shape {
              appearance USE A_ORANGE_FACE
              geometry Box {
                size 0.1 0.9 0.01
              }
            }
          ]
        }
        Transform {
          translation 0.45 0.4 0
          rotation 0 0 1 1.5707996938995747
          children [
            Shape {
              appearance USE A_ORANGE_FACE
              geometry Box {
                size 0.1 0.9 0.01
              }
            }
          ]
        }
        Transform {
          translation 0.45 0 0
          rotation 0 0 1 0.8554
          children [
            Shape {
              appearance USE A_ORANGE_FACE
              geometry Box {
                size 0.07 1.1 0.01
              }
            }
          ]
        }
        Transform {
          translation 0.45 0 0
          rotation 0 0 1 -0.859
          children [
            Shape {
              appearance USE A_ORANGE_FACE
              geometry Box {
                size 0.07 1.1 0.01
              }
            }
          ]
        }
      ]
    }
  ]
  name "solid(3)"
}
DEF S_BOX_FACE4 Solid {
  translation 0.495 0.5 0.45
  rotation 0 1 0 1.5707996938995747
  children [
    Group {
      children [
        Transform {
        }
        Shape {
          appearance USE A_ORANGE_FACE
          geometry Box {
            size 0.08 0.9 0.01
          }
        }
        Transform {
          translation 0.9 0 0
          children [
            Shape {
              appearance USE A_ORANGE_FACE
              geometry Box {
                size 0.08 0.9 0.01
              }
            }
          ]
        }
        Transform {
          translation 0.45 -0.4 0
          rotation 0 0 1 1.5707996938995747
          children [
            Shape {
              appearance USE A_ORANGE_FACE
              geometry Box {
                size 0.1 0.9 0.01
              }
            }
          ]
        }
        Transform {
          translation 0.45 0.4 0
          rotation 0 0 1 1.5707996938995747
          children [
            Shape {
              appearance USE A_ORANGE_FACE
              geometry Box {
                size 0.1 0.9 0.01
              }
            }
          ]
        }
        Transform {
          translation 0.45 0 0
          rotation 0 0 1 0.8554
          children [
            Shape {
              appearance USE A_ORANGE_FACE
              geometry Box {
                size 0.07 1.1 0.01
              }
            }
          ]
        }
        Transform {
          translation 0.45 0 0
          rotation 0 0 1 -0.859
          children [
            Shape {
              appearance USE A_ORANGE_FACE
              geometry Box {
                size 0.07 1.1 0.01
              }
            }
          ]
        }
      ]
    }
  ]
  name "solid(4)"
}
DEF BOX_TOP Solid {
  translation 0 0.975 0
  children [
    Shape {
      appearance USE A_RED_BOTTOM
      geometry Box {
        size 1 0.05 1
      }
    }
  ]
  name "solid(5)"
}
DEF S_CYLINDER Solid {
  translation 0 1.25 0
  children [
    Shape {
      appearance PBRAppearance {
        baseColor 0.12549019607843137 0.2901960784313726 0.5294117647058824
      }
      geometry Cylinder {
        height 0.5
        radius 0.05
      }
    }
    HingeJoint {
      jointParameters HingeJointParameters {
        axis 0 1 0
        minStop 1
        maxStop -1
        staticFriction 0.02
      }
      endPoint Solid {
        translation -3.469446951953614e-18 0.29999999999999977 -0.10000000000000002
        children [
          Shape {
            appearance PBRAppearance {
              baseColor 0.9294117647058824 0.8313725490196079 0
            }
            geometry Box {
              size 0.1 0.1 0.5
            }
          }
          HingeJoint {
            jointParameters HingeJointParameters {
              axis 0 0 1
              anchor 0 0 -0.25
              staticFriction 0.01
            }
            endPoint Solid {
              rotation 0 0 1 0
              children [
                Group {
                  children [
                    Transform {
                      translation 0 0 -0.25
                      children [
                        Shape {
                          appearance DEF A_MILL PBRAppearance {
                            baseColor 0.5411764705882353 0.8862745098039215 0.20392156862745098
                          }
                          geometry Box {
                            size 0.1 0.5 0.02
                          }
                        }
                        Transform {
                          rotation 0 0 1 1.5707996938995747
                          children [
                            Shape {
                              appearance USE A_MILL
                              geometry Box {
                                size 0.1 0.5 0.02
                              }
                            }
                          ]
                        }
                      ]
                    }
                  ]
                }
              ]
              boundingObject Box {
                size 0.1 0.5 0.02
              }
              physics Physics {
              }
            }
          }
        ]
        boundingObject Box {
          size 0.1 0.1 0.5
        }
        physics Physics {
        }
      }
    }
  ]
  name "solid(6)"
}
